[2025-07-22 00:02:18] Error running MFCode.py:
Traceback (most recent call last):
  File "/usr/lib/python3/dist-packages/urllib3/connection.py", line 174, in _new_conn
    conn = connection.create_connection(
           ^^^^^^^^^^^^^^^^^^^^^^^^^^^^^
  File "/usr/lib/python3/dist-packages/urllib3/util/connection.py", line 96, in create_connection
    raise err
  File "/usr/lib/python3/dist-packages/urllib3/util/connection.py", line 86, in create_connection
    sock.connect(sa)
OSError: [Errno 101] Network is unreachable

During handling of the above exception, another exception occurred:

Traceback (most recent call last):
  File "/usr/lib/python3/dist-packages/urllib3/connectionpool.py", line 705, in urlopen
    httplib_response = self._make_request(
                       ^^^^^^^^^^^^^^^^^^^
  File "/usr/lib/python3/dist-packages/urllib3/connectionpool.py", line 388, in _make_request
    self._validate_conn(conn)
  File "/usr/lib/python3/dist-packages/urllib3/connectionpool.py", line 1050, in _validate_conn
    conn.connect()
  File "/usr/lib/python3/dist-packages/urllib3/connection.py", line 358, in connect
    self.sock = conn = self._new_conn()
                       ^^^^^^^^^^^^^^^^
  File "/usr/lib/python3/dist-packages/urllib3/connection.py", line 186, in _new_conn
    raise NewConnectionError(
urllib3.exceptions.NewConnectionError: <urllib3.connection.HTTPSConnection object at 0x7fffb77bfd90>: Failed to establish a new connection: [Errno 101] Network is unreachable

During handling of the above exception, another exception occurred:

Traceback (most recent call last):
  File "/usr/lib/python3/dist-packages/requests/adapters.py", line 489, in send
    resp = conn.urlopen(
           ^^^^^^^^^^^^^
  File "/usr/lib/python3/dist-packages/urllib3/connectionpool.py", line 789, in urlopen
    retries = retries.increment(
              ^^^^^^^^^^^^^^^^^^
  File "/usr/lib/python3/dist-packages/urllib3/util/retry.py", line 594, in increment
    raise MaxRetryError(_pool, url, error or ResponseError(cause))
urllib3.exceptions.MaxRetryError: HTTPSConnectionPool(host='www.rupeevest.com', port=443): Max retries exceeded with url: /home/get_search_data (Caused by NewConnectionError('<urllib3.connection.HTTPSConnection object at 0x7fffb77bfd90>: Failed to establish a new connection: [Errno 101] Network is unreachable'))

During handling of the above exception, another exception occurred:

Traceback (most recent call last):
  File "/home/nikunj/MF_Benchmarks/MFCode.py", line 8, in <module>
    response = requests.get(url)
               ^^^^^^^^^^^^^^^^^
  File "/usr/lib/python3/dist-packages/requests/api.py", line 73, in get
    return request("get", url, params=params, **kwargs)
           ^^^^^^^^^^^^^^^^^^^^^^^^^^^^^^^^^^^^^^^^^^^^
  File "/usr/lib/python3/dist-packages/requests/api.py", line 59, in request
    return session.request(method=method, url=url, **kwargs)
           ^^^^^^^^^^^^^^^^^^^^^^^^^^^^^^^^^^^^^^^^^^^^^^^^^
  File "/usr/lib/python3/dist-packages/requests/sessions.py", line 587, in request
    resp = self.send(prep, **send_kwargs)
           ^^^^^^^^^^^^^^^^^^^^^^^^^^^^^^
  File "/usr/lib/python3/dist-packages/requests/sessions.py", line 701, in send
    r = adapter.send(request, **kwargs)
        ^^^^^^^^^^^^^^^^^^^^^^^^^^^^^^^
  File "/usr/lib/python3/dist-packages/requests/adapters.py", line 565, in send
    raise ConnectionError(e, request=request)
requests.exceptions.ConnectionError: HTTPSConnectionPool(host='www.rupeevest.com', port=443): Max retries exceeded with url: /home/get_search_data (Caused by NewConnectionError('<urllib3.connection.HTTPSConnection object at 0x7fffb77bfd90>: Failed to establish a new connection: [Errno 101] Network is unreachable'))

[2025-07-22 00:02:18] Error running Benchmark.py:
Traceback (most recent call last):
  File "/home/nikunj/MF_Benchmarks/Benchmark.py", line 48, in <module>
    fetch_json_and_save_csv()
  File "/home/nikunj/MF_Benchmarks/Benchmark.py", line 7, in fetch_json_and_save_csv
    with open('MFCodes.csv', 'r') as csvfile:
         ^^^^^^^^^^^^^^^^^^^^^^^^
FileNotFoundError: [Errno 2] No such file or directory: 'MFCodes.csv'

[2025-07-22 00:02:18] Error running Historical_Returns.py:
Traceback (most recent call last):
  File "/home/nikunj/MF_Benchmarks/Historical_Returns.py", line 48, in <module>
    fetch_json_and_save_csv()
  File "/home/nikunj/MF_Benchmarks/Historical_Returns.py", line 9, in fetch_json_and_save_csv
    with open('MFCodes.csv', 'r') as csvfile:
         ^^^^^^^^^^^^^^^^^^^^^^^^
FileNotFoundError: [Errno 2] No such file or directory: 'MFCodes.csv'

[2025-07-22 00:02:18] Error running Index_Latest.py:
Traceback (most recent call last):
  File "/home/nikunj/MF_Benchmarks/Index_Latest.py", line 48, in <module>
    fetch_json_and_save_csv()
  File "/home/nikunj/MF_Benchmarks/Index_Latest.py", line 6, in fetch_json_and_save_csv
    with open('MFCodes.csv', 'r') as csvfile:
         ^^^^^^^^^^^^^^^^^^^^^^^^
FileNotFoundError: [Errno 2] No such file or directory: 'MFCodes.csv'

[2025-07-22 00:02:18] Error running Peer_Comparison.py:
Traceback (most recent call last):
  File "/home/nikunj/MF_Benchmarks/Peer_Comparison.py", line 47, in <module>
    fetch_json_and_save_csv()
  File "/home/nikunj/MF_Benchmarks/Peer_Comparison.py", line 6, in fetch_json_and_save_csv
    with open('MFCodes.csv', 'r') as csvfile:
         ^^^^^^^^^^^^^^^^^^^^^^^^
FileNotFoundError: [Errno 2] No such file or directory: 'MFCodes.csv'

[2025-07-22 00:02:19] Error running Returns_Data.py:
Traceback (most recent call last):
  File "/home/nikunj/MF_Benchmarks/Returns_Data.py", line 47, in <module>
    fetch_json_and_save_csv()
  File "/home/nikunj/MF_Benchmarks/Returns_Data.py", line 6, in fetch_json_and_save_csv
    with open('MFCodes.csv', 'r') as csvfile:
         ^^^^^^^^^^^^^^^^^^^^^^^^
FileNotFoundError: [Errno 2] No such file or directory: 'MFCodes.csv'

[2025-07-22 00:02:19] Error running Scheme_Risk.py:
Traceback (most recent call last):
  File "/home/nikunj/MF_Benchmarks/Scheme_Risk.py", line 47, in <module>
    fetch_json_and_save_csv()
  File "/home/nikunj/MF_Benchmarks/Scheme_Risk.py", line 6, in fetch_json_and_save_csv
    with open('MFCodes.csv', 'r') as csvfile:
         ^^^^^^^^^^^^^^^^^^^^^^^^
FileNotFoundError: [Errno 2] No such file or directory: 'MFCodes.csv'

